[0m04:25:28.059701 [debug] [MainThread]: Sending event: {'category': 'dbt', 'action': 'invocation', 'label': 'start', 'context': [<snowplow_tracker.self_describing_json.SelfDescribingJson object at 0x7f5e9c03f5b0>, <snowplow_tracker.self_describing_json.SelfDescribingJson object at 0x7f5e99d07e50>, <snowplow_tracker.self_describing_json.SelfDescribingJson object at 0x7f5e99d07d90>]}


============================== 04:25:28.065392 | b8251cdd-ee3d-4fe7-915f-314d4416fd0b ==============================
[0m04:25:28.065392 [info ] [MainThread]: Running with dbt=1.7.4
[0m04:25:28.066812 [debug] [MainThread]: running dbt with arguments {'printer_width': '80', 'indirect_selection': 'eager', 'log_cache_events': 'False', 'write_json': 'True', 'partial_parse': 'True', 'cache_selected_only': 'False', 'profiles_dir': '/root/.dbt', 'debug': 'False', 'version_check': 'True', 'log_path': 'logs', 'fail_fast': 'False', 'warn_error': 'None', 'use_colors': 'True', 'use_experimental_parser': 'False', 'no_print': 'None', 'quiet': 'False', 'log_format': 'default', 'invocation_command': 'dbt deps', 'warn_error_options': 'WarnErrorOptions(include=[], exclude=[])', 'static_parser': 'True', 'target_path': 'None', 'introspect': 'True', 'send_anonymous_usage_stats': 'True'}
[0m04:25:28.073195 [error] [MainThread]: Encountered an error:
Runtime Error
  No dbt_project.yml found at expected path /home/src/dbt_project.yml
  Verify that each entry within packages.yml (and their transitive dependencies) contains a file named dbt_project.yml
  
[0m04:25:28.075778 [debug] [MainThread]: Resource report: {"command_name": "deps", "command_wall_clock_time": 0.0215345, "process_user_time": 2.21957, "process_kernel_time": 0.129974, "process_mem_max_rss": "97260", "command_success": false, "process_in_blocks": "0", "process_out_blocks": "0"}
[0m04:25:28.077287 [debug] [MainThread]: Command `dbt deps` failed at 04:25:28.077123 after 0.02 seconds
[0m04:25:28.078612 [debug] [MainThread]: Sending event: {'category': 'dbt', 'action': 'invocation', 'label': 'end', 'context': [<snowplow_tracker.self_describing_json.SelfDescribingJson object at 0x7f5e9c03f5b0>, <snowplow_tracker.self_describing_json.SelfDescribingJson object at 0x7f5e99d44070>, <snowplow_tracker.self_describing_json.SelfDescribingJson object at 0x7f5e99d44ee0>]}
[0m04:25:28.079980 [debug] [MainThread]: Flushing usage events
[0m22:53:43.418222 [debug] [MainThread]: Sending event: {'category': 'dbt', 'action': 'invocation', 'label': 'start', 'context': [<snowplow_tracker.self_describing_json.SelfDescribingJson object at 0x7f78dee835b0>, <snowplow_tracker.self_describing_json.SelfDescribingJson object at 0x7f78dcb7fe50>, <snowplow_tracker.self_describing_json.SelfDescribingJson object at 0x7f78dcb7fdf0>]}


============================== 22:53:43.420642 | 6305f676-e972-4ff4-b152-1f1d35e1f9f2 ==============================
[0m22:53:43.420642 [info ] [MainThread]: Running with dbt=1.7.4
[0m22:53:43.421485 [debug] [MainThread]: running dbt with arguments {'printer_width': '80', 'indirect_selection': 'eager', 'write_json': 'True', 'log_cache_events': 'False', 'partial_parse': 'True', 'cache_selected_only': 'False', 'warn_error': 'None', 'fail_fast': 'False', 'version_check': 'True', 'log_path': 'logs', 'debug': 'False', 'profiles_dir': '/root/.dbt', 'use_colors': 'True', 'use_experimental_parser': 'False', 'no_print': 'None', 'quiet': 'False', 'warn_error_options': 'WarnErrorOptions(include=[], exclude=[])', 'invocation_command': 'dbt deps', 'introspect': 'True', 'log_format': 'default', 'target_path': 'None', 'static_parser': 'True', 'send_anonymous_usage_stats': 'True'}
[0m22:53:43.422478 [error] [MainThread]: Encountered an error:
Runtime Error
  No dbt_project.yml found at expected path /home/src/dbt_project.yml
  Verify that each entry within packages.yml (and their transitive dependencies) contains a file named dbt_project.yml
  
[0m22:53:43.423759 [debug] [MainThread]: Resource report: {"command_name": "deps", "command_wall_clock_time": 0.008405678, "process_user_time": 1.820201, "process_kernel_time": 0.050281, "process_mem_max_rss": "97380", "process_in_blocks": "8", "command_success": false, "process_out_blocks": "0"}
[0m22:53:43.424792 [debug] [MainThread]: Command `dbt deps` failed at 22:53:43.424569 after 0.01 seconds
[0m22:53:43.425670 [debug] [MainThread]: Sending event: {'category': 'dbt', 'action': 'invocation', 'label': 'end', 'context': [<snowplow_tracker.self_describing_json.SelfDescribingJson object at 0x7f78dee835b0>, <snowplow_tracker.self_describing_json.SelfDescribingJson object at 0x7f78dcbbc070>, <snowplow_tracker.self_describing_json.SelfDescribingJson object at 0x7f78dcbbcee0>]}
[0m22:53:43.426375 [debug] [MainThread]: Flushing usage events
